# Promise

## 1. why

+ 举个例子我们购票的过程，查询，买票一列的过程，都是一个个的回调函数，并且都是基于上一个的前提继续回调，这就会形成回调函数里嵌套了回调函数，形成的回调地狱。
+ Promise就是解决异步编程的一个解决方案，目的在于让代码更优雅。异步操作以同步的流程表达出来，避免层层嵌套。

## 2. 含义

Promise 是异步编程的一种解决方案，原生提供了`Promise`对象。

所谓`Promise`，简单说就是一个容器，里面保存着某个未来才会结束的事件（通常是一个异步操作）的结果。**我理解为Promise保存着一个结果，当状态变成失败或成功时候，.then获取里面的结果。**

从语法上说，Promise 是一个对象，从它可以获取异步操作的消息。Promise 提供统一的 API，各种异步操作都可以用同样的方法进行处理。

+ `Promise`对象有以下两个特点。

（1）对象的状态不受外界影响。`Promise`对象代表一个异步操作，有三种状态：`pending`（进行中）、`fulfilled`（已成功）和`rejected`（已失败）。只有异步操作的结果，可以决定当前是哪一种状态，任何其他操作都无法改变这个状态。这也是`Promise`这个名字的由来，它的英语意思就是“承诺”，表示其他手段无法改变。

（2）一旦状态改变，就不会再变，任何时候都可以得到这个结果。`Promise`对象的状态改变，只有两种可能：从`pending`变为`fulfilled`和从`pending`变为`rejected`。只要这两种情况发生，状态就凝固了，不会再变了，会一直保持这个结果，这时就称为 resolved（已定型）。如果改变已经发生了，你再对`Promise`对象添加回调函数，也会立即得到这个结果。这与事件（Event）完全不同，事件的特点是，如果你错过了它，再去监听，是得不到结果的。

注意，为了行文方便，本章后面的`resolved`统一只指`fulfilled`状态，不包含`rejected`状态。

有了`Promise`对象，就可以将异步操作以同步操作的流程表达出来，避免了层层嵌套的回调函数。此外，`Promise`对象提供统一的接口，使得控制异步操作更加容易。

`Promise`也有一些缺点。首先，无法取消`Promise`，一旦新建它就会立即执行，无法中途取消。其次，如果不设置回调函数，`Promise`内部抛出的错误，不会反应到外部。第三，当处于`pending`状态时，无法得知目前进展到哪一个阶段（刚刚开始还是即将完成）。

## 3. 基本用法

`Promise`对象是一个构造函数，用来生成`Promise`实例。

```js
const promise = new Promise(function(resolve, reject) {
  // ... some code

  // 这里可以理解成，Promise成功或失败就会把一个包含value/error的Promise对象抛出，之后由我们的.then方法捕获，Promise会告知你是失败还是成功。成功使用.then的第一个回调函数参数，失败使用第二个
  if (/* 异步操作成功 */){
    resolve(value);
  } else {
    reject(error);
  }
});

//then方法可以接受两个回调函数作为参数。第一个回调函数是Promise对象的状态变为resolved时调用，第二个回调函数是Promise对象的状态变为rejected时调用。这两个函数都是可选的.它们都接受Promise对象传出的值作为参数。
promise.then(function(value) {
  // success
}, function(error) {
  // failure
});
```

`Promise`构造函数接受一个函数作为参数，该函数的两个参数分别是`resolve`和`reject`。它们是两个函数，由 JavaScript 引擎提供，不用自己部署。

如果调用`resolve`函数和`reject`函数时带有参数，那么它们的参数会被传递给回调函数。

`resolve`函数的作用是，将`Promise`对象的状态从“未完成”变为“成功”（即从 pending 变为 resolved），在异步操作成功时调用，并将异步操作的结果，作为参数传递出去；`reject`函数的作用是，将`Promise`对象的状态从“未完成”变为“失败”（即从 pending 变为 rejected），在异步操作失败时调用，并将异步操作报出的错误，作为参数传递出去。

`Promise`实例生成以后，可以用`then`方法分别指定`resolved`状态和`rejected`状态的回调函数。

```js
function timeout(ms) {
  return new Promise((resolve, reject) => {
    setTimeout(resolve, ms, 'done');  // setTimeout第三个参数是作为第一个参数回调函数的参数传进去
  });
}
console.log('timeout(100)', timeout(100)) // timeout(100) Promise { <pending> } 返回应该是pending状态，因为放到异步了，直接先打印，再继续执行setTimeout里的内容

timeout(100).then((value) => {
  console.log(value);
});
```

```js
function foo(value) {
    return new Promise((resolve, reject) => {
        resolve(value)
        reject(0)
    });
}

console.log('foo(100)', foo(100)) // Promise { 100 }

foo(100).then((value) => { console.log(value); }, (err) => { console.log('err', err) });

// 替换抛出顺序
function foo(value) {
    return new Promise((resolve, reject) => {
        // 这里
        reject(0)
        resolve(value)
    });
}

console.log('foo(100)', foo(100)) // Promise { <rejected> 0 }

foo(100).then((value) => { console.log(value); }, (err) => { console.log('err', err) });
```

+ Promise 新建后就会立即执行。**说明了Promise是同步的**，.then是异步的，会等待Promise出现结果再执行

```js
let promise = new Promise(function(resolve, reject) {
  console.log('Promise');
  resolve();
});

promise.then(function() {
  console.log('resolved.');
});

console.log('Hi!');

// Promise
// Hi!
// resolved
```

`reaolve`函数除了正常的值以外，还可以抛出另一个Promise实例。

`reject`函数的参数通常是`Error`对象的实例。

```js
const p1 = new Promise(function (resolve, reject) {
  setTimeout(() => reject(new Error('fail')), 3000)
})

const p2 = new Promise(function (resolve, reject) {
  setTimeout(() => resolve(p1), 1000)
})

p2
  .then(result => console.log(result))
  .catch(error => console.log(error))
// Error: fail
```

+ 这时`p1`的状态就会传递给`p2`，也就是说，`p1`的状态决定了`p2`的状态。如果`p1`的状态是`pending`，那么`p2`的回调函数就会等待`p1`的状态改变；如果`p1`的状态已经是`resolved`或者`rejected`，那么`p2`的回调函数将会立刻执行。

+ 调用`resolve`或`reject`并不会终结 Promise 的参数函数的执行。
+ **我认为`resolve`是异步的的，总是会在本轮事件循环的末尾执行，总是晚于本轮循环的同步任务**
+ 一般来说，调用`resolve`或`reject`以后，Promise 的使命就完成了，后继操作应该放到`then`方法里面，而不应该直接写在`resolve`或`reject`的后面。所以，最好在它们前面加上`return`语句，这样就不会有意外。

```js
new Promise((resolve, reject) => {
  return resolve(1);
  // 后面的语句不会执行
  console.log(2);
})
```

## 4. `Promise.prototype.then()`

+ 它的作用是为 Promise 实例添加状态改变时的回调函数。
+ `then`方法的第一个参数是`resolved`状态的回调函数，第二个参数是`rejected`状态的回调函数，它们都是可选的。

## 5. `Promise.prototype.catch()`

+ `Promise.prototype.catch()`方法是`.then(null, rejection)`或`.then(undefined, rejection)`的别名，用于指定发生错误时的回调函数。
+ `then()`方法指定的回调函数，如果运行中抛出错误，也会被`catch()`方法捕获。

```js
const promise = new Promise(function(resolve, reject) {
  resolve('ok');
  throw new Error('test');
});
promise
  .then(function(value) { console.log(value) })
  .catch(function(error) { console.log(error) });
// ok
```

+ 如果 Promise 状态已经变成`resolved`，再抛出错误是无效的。因为 Promise 的状态一旦改变，就永久保持该状态，不会再变了。

```js
const promise = new Promise(function(resolve, reject) {
  throw new Error('test');
  console.log('111')  // 这里不会被打印
  resolve('ok');
});
promise
  .then(function(value) { console.log(value) })
  .catch(function(error) { console.log(error) });

// Error: test
```

+ 这里可以发现`throw`抛出异常和`reject`一样，直接跳到`catch`被抓住。
+ Promise 对象的错误具有“冒泡”性质，会一直向后传递，直到被捕获为止。也就是说，错误总是会被下一个`catch`语句捕获。意味着，如果多个错误，最终会一直传递到某一个catch上，然后直接一起消化掉。

```js
const someAsyncThing = function() {
  return new Promise(function(resolve, reject) {
    // 下面一行会报错，因为x没有声明
    resolve(x + 2);
  });
};

someAsyncThing().then(function() {
  console.log('everything is great');
});

setTimeout(() => { console.log(123) }, 2000);
// Uncaught (in promise) ReferenceError: x is not defined
// 123
```

+ `Promise`的一个优点：假设报错没有使用`catch()`方法指定错误处理回调函数，`Promise`对象抛出的错误不会传递到外层代码，即不会有任何反应。

```js
const someAsyncThing = function() {
  return new Promise(function(resolve, reject) {
    // 下面一行会报错，因为x没有声明
    resolve(x + 2);
  });
};

someAsyncThing().then(function() {
  console.log('everything is great');
});

setTimeout(() => { console.log(123) }, 2000);
// Uncaught (in promise) ReferenceError: x is not defined
// 123
```

+ `someAsyncThing()`函数产生的 Promise 对象，内部有语法错误。浏览器运行到这一行，会打印出错误提示`ReferenceError: x is not defined`，但是不会退出进程、终止脚本执行，2 秒之后还是会输出`123`。这就是说，Promise 内部的错误不会影响到 Promise 外部的代码，通俗的说法就是“Promise 会吃掉错误”。

```js
const promise = new Promise(function (resolve, reject) {
  resolve('ok');
  setTimeout(function () { throw new Error('test') }, 0)
});
promise.then(function (value) { console.log(value) });
// ok
// Uncaught Error: test
```

+ 上面代码中，Promise 指定在下一轮“事件循环”再抛出错误。到了那个时候，Promise 的运行已经结束了，所以这个错误是在 Promise 函数体外抛出的，会冒泡到最外层，成了未捕获的错误。
+ 一般总是建议，Promise 对象后面要跟`catch()`方法，这样可以处理 Promise 内部发生的错误。`catch()`方法返回的还是一个 Promise 对象，因此后面还可以接着调用`then()`方法。
+ 如果没有报错会跳过`catch`。



## 后面暂时不看了





















